Workbook

Sheet 术语表
A1: 序号 | B1: 术语词条 | C1: 术语英文 | D1: 派生词 | E1: 术语定义 | F1: 术语条目编号 | G1: 同义词/简化词 | H1: 缩略语 | I1: 符号 | J1: 来源 | K1: 注 | L1: 性质 | M1: 体系序号 | N1: 标准号 | O1: 标准名称 | Q1: 标准所属专业 | R1: 一级条标题 | S1: 二级条标题 | T1: 三级条标题 | U1: 是否在技术要素中提及 | V1: 术语字数
A2: 1 | B2: 油田化学 | C2: oilfield chemistry | E2: 利用化学方法研究解决油气田勘探开发作业过程中全生命周期化学问题的学科。 | F2: 3.1 | M2: =VLOOKUP(N2,[1]储层改造标准目录!$A:$B,2,0) -> 1 | N2: SY/T 5510-2021 | O2: 油田化学常用术语 | Q2: 油田化学剂及材料 | R2: 通用 | U2: {=SUM(LEN([2]正文!$F:$F)-LEN(SUBSTITUTE([2]正文!$F:$F,B2,"")))/LEN(B2)} -> 1 | V2: =LEN(B2) -> 4
A3: 2 | B3: 油田化学剂/材料 | C3: oilfield chemicals/materials | D3: # | E3: 钻井完井、压裂酸化、采油采气、提高采收率、油气水处理及集输等过程中，用化学方法解决问题所涉及的化学剂/材料。 | F3: 3.2 | G3: 油田化学剂、油田化学材料 | M3: =VLOOKUP(N3,[1]储层改造标准目录!$A:$B,2,0) -> 1 | N3: SY/T 5510-2021 | O3: 油田化学常用术语 | Q3: 油田化学剂及材料 | R3: 通用 | U3: {=SUM(LEN([2]正文!$F:$F)-LEN(SUBSTITUTE([2]正文!$F:$F,B3,"")))/LEN(B3)} -> 0 | V3: =LEN(B3) -> 8
B4: 油田化学剂 | C4: oilfield chemicals | D4: * | F4: 3.2-1 | G4: 油田化学材料 | M4: =VLOOKUP(N4,[1]储层改造标准目录!$A:$B,2,0) -> 1 | N4: SY/T 5510-2021 | O4: 油田化学常用术语 | Q4: 油田化学剂及材料 | R4: 通用 | U4: {=SUM(LEN([2]正文!$F:$F)-LEN(SUBSTITUTE([2]正文!$F:$F,B4,"")))/LEN(B4)} -> 1 | V4: =LEN(B4) -> 5
B5: 油田化学材料 | C5: oilfield materials | D5: * | F5: 3.2-2 | G5: 油田化学剂 | M5: =VLOOKUP(N5,[1]储层改造标准目录!$A:$B,2,0) -> 1 | N5: SY/T 5510-2021 | O5: 油田化学常用术语 | Q5: 油田化学剂及材料 | R5: 通用 | U5: {=SUM(LEN([2]正文!$F:$F)-LEN(SUBSTITUTE([2]正文!$F:$F,B5,"")))/LEN(B5)} -> 0 | V5: =LEN(B5) -> 6
A6: 3 | B6: 表面活性剂 | C6: surfactant | E6: 分子由亲水基团和亲油基团组成，能显著降低表/界面张力的化学剂。 | F6: 3.3 | M6: =VLOOKUP(N6,[1]储层改造标准目录!$A:$B,2,0) -> 1 | N6: SY/T 5510-2021 | O6: 油田化学常用术语 | Q6: 油田化学剂及材料 | R6: 通用 | U6: {=SUM(LEN([2]正文!$F:$F)-LEN(SUBSTITUTE([2]正文!$F:$F,B6,"")))/LEN(B6)} -> 56 | V6: =LEN(B6) -> 5
A7: 4 | B7: 聚合物 | C7: polymer | E7: 由重复结构单元组成的高分子化合物。 | F7: 3.4 | M7: =VLOOKUP(N7,[1]储层改造标准目录!$A:$B,2,0) -> 1 | N7: SY/T 5510-2021 | O7: 油田化学常用术语 | Q7: 油田化学剂及材料 | R7: 通用 | U7: {=SUM(LEN([2]正文!$F:$F)-LEN(SUBSTITUTE([2]正文!$F:$F,B7,"")))/LEN(B7)} -> 31 | V7: =LEN(B7) -> 3
A8: 5 | B8: 纳米材料 | C8: nanometer material | E8: 线度小于100nm的材料。 | F8: 3.5 | M8: =VLOOKUP(N8,[1]储层改造标准目录!$A:$B,2,0) -> 1 | N8: SY/T 5510-2021 | O8: 油田化学常用术语 | Q8: 油田化学剂及材料 | R8: 通用 | U8: {=SUM(LEN([2]正文!$F:$F)-LEN(SUBSTITUTE([2]正文!$F:$F,B8,"")))/LEN(B8)} -> 0 | V8: =LEN(B8) -> 4
A9: 6 | B9: 化学改性 | C9: chemical modification | E9: 用化学方法改变物质的物理化学性质。 | F9: 3.6 | M9: =VLOOKUP(N9,[1]储层改造标准目录!$A:$B,2,0) -> 1 | N9: SY/T 5510-2021 | O9: 油田化学常用术语 | Q9: 油田化学剂及材料 | R9: 通用 | U9: {=SUM(LEN([2]正文!$F:$F)-LEN(SUBSTITUTE([2]正文!$F:$F,B9,"")))/LEN(B9)} -> 0 | V9: =LEN(B9) -> 4
A10: 7 | B10: 配伍性（相容性） | C10: compatibility | D10: # | E10: 工作液体系中各成分间或体系与环境间不发生影响其使用性能的化学和物理变化的性质。 | F10: 3.7 | M10: =VLOOKUP(N10,[1]储层改造标准目录!$A:$B,2,0) -> 1 | N10: SY/T 5510-2021 | O10: 油田化学常用术语 | Q10: 油田化学剂及材料 | R10: 通用 | U10: {=SUM(LEN([2]正文!$F:$F)-LEN(SUBSTITUTE([2]正文!$F:$F,B10,"")))/LEN(B10)} -> 0 | V10: =LEN(B10) -> 8
B11: 配伍性 | D11: * | F11: 3.7-1 | M11: =VLOOKUP(N11,[1]储层改造标准目录!$A:$B,2,0) -> 1 | N11: SY/T 5510-2021 | O11: 油田化学常用术语 | Q11: 油田化学剂及材料 | R11: 通用 | U11: {=SUM(LEN([2]正文!$F:$F)-LEN(SUBSTITUTE([2]正文!$F:$F,B11,"")))/LEN(B11)} -> 76 | V11: =LEN(B11) -> 3
B12: 相容性 | D12: * | F12: 3.7-2 | M12: =VLOOKUP(N12,[1]储层改造标准目录!$A:$B,2,0) -> 1 | N12: SY/T 5510-2021 | O12: 油田化学常用术语 | Q12: 油田化学剂及材料 | R12: 通用 | U12: {=SUM(LEN([2]正文!$F:$F)-LEN(SUBSTITUTE([2]正文!$F:$F,B12,"")))/LEN(B12)} -> 1 | V12: =LEN(B12) -> 3
A13: 8 | B13: 协同效应 | C13: synergism | E13: 两种或两种以上化学剂复配使用，其效果优于同条件下化学剂单独使用效果简单加和的效应。 | F13: 3.8 | M13: =VLOOKUP(N13,[1]储层改造标准目录!$A:$B,2,0) -> 1 | N13: SY/T 5510-2021 | O13: 油田化学常用术语 | Q13: 油田化学剂及材料 | R13: 通用 | U13: {=SUM(LEN([2]正文!$F:$F)-LEN(SUBSTITUTE([2]正文!$F:$F,B13,"")))/LEN(B13)} -> 0 | V13: =LEN(B13) -> 4
A14: 9 | B14: 稳定性 | C14: stability | E14: 油田化学剂或工作液体系在使用环境条件下保持其原有性质的能力。 | F14: 3.9 | M14: =VLOOKUP(N14,[1]储层改造标准目录!$A:$B,2,0) -> 1 | N14: SY/T 5510-2021 | O14: 油田化学常用术语 | Q14: 油田化学剂及材料 | R14: 通用 | U14: {=SUM(LEN([2]正文!$F:$F)-LEN(SUBSTITUTE([2]正文!$F:$F,B14,"")))/LEN(B14)} -> 33 | V14: =LEN(B14) -> 3
A15: 10 | B15: 流变性 | C15: rheology | E15: 在外力作用下化学剂/工作液的流动和形变性质。 | F15: 3.10 | M15: =VLOOKUP(N15,[1]储层改造标准目录!$A:$B,2,0) -> 1 | N15: SY/T 5510-2021 | O15: 油田化学常用术语 | Q15: 油田化学剂及材料 | R15: 通用 | U15: {=SUM(LEN([2]正文!$F:$F)-LEN(SUBSTITUTE([2]正文!$F:$F,B15,"")))/LEN(B15)} -> 4 | V15: =LEN(B15) -> 3
A16: 11 | B16: 黏弹性 | C16: viscoelasticity | E16: 在外力作用下材料/工作液表现出黏性和弹性的双重性质。 | F16: 3.11 | M16: =VLOOKUP(N16,[1]储层改造标准目录!$A:$B,2,0) -> 1 | N16: SY/T 5510-2021 | O16: 油田化学常用术语 | Q16: 油田化学剂及材料 | R16: 通用 | U16: {=SUM(LEN([2]正文!$F:$F)-LEN(SUBSTITUTE([2]正文!$F:$F,B16,"")))/LEN(B16)} -> 29 | V16: =LEN(B16) -> 3
A17: 12 | B17: 剪切稀性 | C17: shear thinming behavior | E17: 化学剂溶液/工作液的表观黏度随剪切速率增加而降低的特性。 | F17: 3.12 | M17: =VLOOKUP(N17,[1]储层改造标准目录!$A:$B,2,0) -> 1 | N17: SY/T 5510-2021 | O17: 油田化学常用术语 | Q17: 油田化学剂及材料 | R17: 通用 | U17: {=SUM(LEN([2]正文!$F:$F)-LEN(SUBSTITUTE([2]正文!$F:$F,B17,"")))/LEN(B17)} -> 0 | V17: =LEN(B17) -> 4
A18: 13 | B18: 交联 | C18: crosslinking | E18: 聚合物分子通过化学反应形成网状结构的过程。 | F18: 3.13 | M18: =VLOOKUP(N18,[1]储层改造标准目录!$A:$B,2,0) -> 1 | N18: SY/T 5510-2021 | O18: 油田化学常用术语 | Q18: 油田化学剂及材料 | R18: 通用 | U18: {=SUM(LEN([2]正文!$F:$F)-LEN(SUBSTITUTE([2]正文!$F:$F,B18,"")))/LEN(B18)} -> 154 | V18: =LEN(B18) -> 2
A19: 14 | B19: 凝（冻）胶 | C19: gel | D19: # | E19: 溶液在一定条件下通过物理或化学作用互相连接形成网状结构的体系。 | F19: 3.14 | M19: =VLOOKUP(N19,[1]储层改造标准目录!$A:$B,2,0) -> 1 | N19: SY/T 5510-2021 | O19: 油田化学常用术语 | Q19: 油田化学剂及材料 | R19: 通用 | U19: {=SUM(LEN([2]正文!$F:$F)-LEN(SUBSTITUTE([2]正文!$F:$F,B19,"")))/LEN(B19)} -> 0 | V19: =LEN(B19) -> 5
B20: 凝胶 | D20: * | F20: 3.14-1 | M20: =VLOOKUP(N20,[1]储层改造标准目录!$A:$B,2,0) -> 1 | N20: SY/T 5510-2021 | O20: 油田化学常用术语 | Q20: 油田化学剂及材料 | R20: 通用 | U20: {=SUM(LEN([2]正文!$F:$F)-LEN(SUBSTITUTE([2]正文!$F:$F,B20,"")))/LEN(B20)} -> 0 | V20: =LEN(B20) -> 2
B21: 冻胶 | D21: * | F21: 3.14-2 | M21: =VLOOKUP(N21,[1]储层改造标准目录!$A:$B,2,0) -> 1 | N21: SY/T 5510-2021 | O21: 油田化学常用术语 | Q21: 油田化学剂及材料 | R21: 通用 | U21: {=SUM(LEN([2]正文!$F:$F)-LEN(SUBSTITUTE([2]正文!$F:$F,B21,"")))/LEN(B21)} -> 126 | V21: =LEN(B21) -> 2
A22: 15 | B22: 破胶 | C22: gel break | E22: 凝/冻胶等体系的网状结构被破坏，体系黏度大幅度降低的过程。 | F22: 3.15 | M22: =VLOOKUP(N22,[1]储层改造标准目录!$A:$B,2,0) -> 1 | N22: SY/T 5510-2021 | O22: 油田化学常用术语 | Q22: 油田化学剂及材料 | R22: 通用 | U22: {=SUM(LEN([2]正文!$F:$F)-LEN(SUBSTITUTE([2]正文!$F:$F,B22,"")))/LEN(B22)} -> 224 | V22: =LEN(B22) -> 2
A23: 16 | B23: 降解 | C23: degradation | E23: 在物理、化学或生物因素作用下，化学剂及材料发生断链/分解引发其性能显著变化的过程。 | F23: 3.16 | M23: =VLOOKUP(N23,[1]储层改造标准目录!$A:$B,2,0) -> 1 | N23: SY/T 5510-2021 | O23: 油田化学常用术语 | Q23: 油田化学剂及材料 | R23: 通用 | U23: {=SUM(LEN([2]正文!$F:$F)-LEN(SUBSTITUTE([2]正文!$F:$F,B23,"")))/LEN(B23)} -> 22 | V23: =LEN(B23) -> 2
A24: 17 | B24: 乳化 | C24: emulsification | E24: 互不相溶的两液相中的一相以微小液滴分散在另一液相的化学现象。 | F24: 3.17 | M24: =VLOOKUP(N24,[1]储层改造标准目录!$A:$B,2,0) -> 1 | N24: SY/T 5510-2021 | O24: 油田化学常用术语 | Q24: 油田化学剂及材料 | R24: 通用 | U24: {=SUM(LEN([2]正文!$F:$F)-LEN(SUBSTITUTE([2]正文!$F:$F,B24,"")))/LEN(B24)} -> 32 | V24: =LEN(B24) -> 2
A25: 18 | B25: 破乳 | C25: demulsification | E25: 使乳状液两相分离的现象。 | F25: 3.18 | M25: =VLOOKUP(N25,[1]储层改造标准目录!$A:$B,2,0) -> 1 | N25: SY/T 5510-2021 | O25: 油田化学常用术语 | Q25: 油田化学剂及材料 | R25: 通用 | U25: {=SUM(LEN([2]正文!$F:$F)-LEN(SUBSTITUTE([2]正文!$F:$F,B25,"")))/LEN(B25)} -> 22 | V25: =LEN(B25) -> 2
A26: 19 | B26: 吸附 | C26: adsorption | E26: 化学剂在相界面上富集的现象。 | F26: 3.19 | M26: =VLOOKUP(N26,[1]储层改造标准目录!$A:$B,2,0) -> 1 | N26: SY/T 5510-2021 | O26: 油田化学常用术语 | Q26: 油田化学剂及材料 | R26: 通用 | U26: {=SUM(LEN([2]正文!$F:$F)-LEN(SUBSTITUTE([2]正文!$F:$F,B26,"")))/LEN(B26)} -> 13 | V26: =LEN(B26) -> 2
A27: 20 | B27: 润湿 | C27: wetting | E27: 液体在与固体接触时，沿固体表面扩展的现象。 | F27: 3.20 | M27: =VLOOKUP(N27,[1]储层改造标准目录!$A:$B,2,0) -> 1 | N27: SY/T 5510-2021 | O27: 油田化学常用术语 | Q27: 油田化学剂及材料 | R27: 通用 | U27: {=SUM(LEN([2]正文!$F:$F)-LEN(SUBSTITUTE([2]正文!$F:$F,B27,"")))/LEN(B27)} -> 48 | V27: =LEN(B27) -> 2
A28: 21 | B28: 润湿反转 | C28: wettability alteration | E28: 岩石表面在一定条件下亲水性和亲油性互相转化的现象。 | F28: 3.21 | M28: =VLOOKUP(N28,[1]储层改造标准目录!$A:$B,2,0) -> 1 | N28: SY/T 5510-2021 | O28: 油田化学常用术语 | Q28: 油田化学剂及材料 | R28: 通用 | U28: {=SUM(LEN([2]正文!$F:$F)-LEN(SUBSTITUTE([2]正文!$F:$F,B28,"")))/LEN(B28)} -> 0 | V28: =LEN(B28) -> 4
A29: 22 | B29: 分散 | C29: dispersion | E29: 不相溶固体/液体/气体以微小颗粒分布于溶液中的过程。 | F29: 3.22 | M29: =VLOOKUP(N29,[1]储层改造标准目录!$A:$B,2,0) -> 1 | N29: SY/T 5510-2021 | O29: 油田化学常用术语 | Q29: 油田化学剂及材料 | R29: 通用 | U29: {=SUM(LEN([2]正文!$F:$F)-LEN(SUBSTITUTE([2]正文!$F:$F,B29,"")))/LEN(B29)} -> 22 | V29: =LEN(B29) -> 2
A30: 23 | B30: 发泡 | C30: foaming | E30: 固体或液体中形成气泡的过程。 | F30: 3.23 | M30: =VLOOKUP(N30,[1]储层改造标准目录!$A:$B,2,0) -> 1 | N30: SY/T 5510-2021 | O30: 油田化学常用术语 | Q30: 油田化学剂及材料 | R30: 通用 | U30: {=SUM(LEN([2]正文!$F:$F)-LEN(SUBSTITUTE([2]正文!$F:$F,B30,"")))/LEN(B30)} -> 0 | V30: =LEN(B30) -> 2
A31: 24 | B31: 消泡 | C31: antifoam | E31: 泡沫逐渐减少或消失的过程。 | F31: 3.24 | M31: =VLOOKUP(N31,[1]储层改造标准目录!$A:$B,2,0) -> 1 | N31: SY/T 5510-2021 | O31: 油田化学常用术语 | Q31: 油田化学剂及材料 | R31: 通用 | U31: {=SUM(LEN([2]正文!$F:$F)-LEN(SUBSTITUTE([2]正文!$F:$F,B31,"")))/LEN(B31)} -> 3 | V31: =LEN(B31) -> 2
A32: 25 | B32: 絮凝 | C32: flocculate | E32: 液体中悬浮微粒聚结成絮状物的过程。 | F32: 3.25 | M32: =VLOOKUP(N32,[1]储层改造标准目录!$A:$B,2,0) -> 1 | N32: SY/T 5510-2021 | O32: 油田化学常用术语 | Q32: 油田化学剂及材料 | R32: 通用 | U32: {=SUM(LEN([2]正文!$F:$F)-LEN(SUBSTITUTE([2]正文!$F:$F,B32,"")))/LEN(B32)} -> 14 | V32: =LEN(B32) -> 2
A33: 26 | B33: 缓蚀 | C33: inhibit corrosion | E33: 抑制或延缓金属等材料被腐蚀的过程。 | F33: 3.26 | M33: =VLOOKUP(N33,[1]储层改造标准目录!$A:$B,2,0) -> 1 | N33: SY/T 5510-2021 | O33: 油田化学常用术语 | Q33: 油田化学剂及材料 | R33: 通用 | U33: {=SUM(LEN([2]正文!$F:$F)-LEN(SUBSTITUTE([2]正文!$F:$F,B33,"")))/LEN(B33)} -> 46 | V33: =LEN(B33) -> 2
A34: 27 | B34: 防垢 | C34: scale inhibit | E34: 防止或延缓溶液中结垢的过程。 | F34: 3.27 | M34: =VLOOKUP(N34,[1]储层改造标准目录!$A:$B,2,0) -> 1 | N34: SY/T 5510-2021 | O34: 油田化学常用术语 | Q34: 油田化学剂及材料 | R34: 通用 | U34: {=SUM(LEN([2]正文!$F:$F)-LEN(SUBSTITUTE([2]正文!$F:$F,B34,"")))/LEN(B34)} -> 6 | V34: =LEN(B34) -> 2
A35: 28 | B35: 除垢 | C35: scale removal | E35: 消除有机垢、无机垢的过程。 | F35: 3.28 | M35: =VLOOKUP(N35,[1]储层改造标准目录!$A:$B,2,0) -> 1 | N35: SY/T 5510-2021 | O35: 油田化学常用术语 | Q35: 油田化学剂及材料 | R35: 通用 | U35: {=SUM(LEN([2]正文!$F:$F)-LEN(SUBSTITUTE([2]正文!$F:$F,B35,"")))/LEN(B35)} -> 0 | V35: =LEN(B35) -> 2
A36: 29 | B36: 杀菌 | C36: sterllize | E36: 抑制或杀灭溶液中的微生物的方法。 | F36: 3.29 | M36: =VLOOKUP(N36,[1]储层改造标准目录!$A:$B,2,0) -> 1 | N36: SY/T 5510-2021 | O36: 油田化学常用术语 | Q36: 油田化学剂及材料 | R36: 通用 | U36: {=SUM(LEN([2]正文!$F:$F)-LEN(SUBSTITUTE([2]正文!$F:$F,B36,"")))/LEN(B36)} -> 34 | V36: =LEN(B36) -> 2
A37: 30 | B37: 除气 | C37: deaerate/degas | E37: 除掉溶液中所溶解的氧气、二氧化碳及硫化氢等气体的过程。 | F37: 3.30 | M37: =VLOOKUP(N37,[1]储层改造标准目录!$A:$B,2,0) -> 1 | N37: SY/T 5510-2021 | O37: 油田化学常用术语 | Q37: 油田化学剂及材料 | R37: 通用 | U37: {=SUM(LEN([2]正文!$F:$F)-LEN(SUBSTITUTE([2]正文!$F:$F,B37,"")))/LEN(B37)} -> 0 | V37: =LEN(B37) -> 2
A38: 31 | B38: 解堵 | C38: blocking remove | E38: 以物理化学方法解除井筒及油藏堵塞的过程。 | F38: 3.31 | M38: =VLOOKUP(N38,[1]储层改造标准目录!$A:$B,2,0) -> 1 | N38: SY/T 5510-2021 | O38: 油田化学常用术语 | Q38: 油田化学剂及材料 | R38: 通用 | U38: {=SUM(LEN([2]正文!$F:$F)-LEN(SUBSTITUTE([2]正文!$F:$F,B38,"")))/LEN(B38)} -> 41 | V38: =LEN(B38) -> 2
... A41: 34 | B41: 表面张力 | C41: surface tension | E41: 气体与液体或固体接触时引起自动收缩力。 | F41: 3.34 | M41: =VLOOKUP(N41,[1]储层改造标准目录!$A:$B,2,0) -> 1 | N41: SY/T 5510-2021 | O41: 油田化学常用术语 | Q41: 油田化学剂及材料 | R41: 通用 | U41: {=SUM(LEN([2]正文!$F:$F)-LEN(SUBSTITUTE([2]正文!$F:$F,B41,"")))/LEN(B41)} -> 65 | V41: =LEN(B41) -> 4
A42: 35 | B42: 亲水亲油平衡值 | C42: hydrophile-lipophile balance value （HLB） | E42: 表征表面活性剂的亲水亲油能力关系的数值。 | F42: 3.35 | H42: =MID(C42,FIND("（",C42)+1,(FIND("）",C42)-FIND("（",C42)-1)) -> HLB | M42: =VLOOKUP(N42,[1]储层改造标准目录!$A:$B,2,0) -> 1 | N42: SY/T 5510-2021 | O42: 油田化学常用术语 | Q42: 油田化学剂及材料 | R42: 通用 | U42: {=SUM(LEN([2]正文!$F:$F)-LEN(SUBSTITUTE([2]正文!$F:$F,B42,"")))/LEN(B42)} -> 0 | V42: =LEN(B42) -> 7
...
